Traceback (most recent call last):
  File "file-tests/testTraceback.py", line 7, in <module>
    foo(lst)
  File "file-tests/testTraceback.py", line 5, in foo
    print(lst[10])
IndexError: list index out of range
