Traceback (most recent call last):
  File "file-tests/testTraceback3.py", line 1, in <module>
    print([1,2,3][10])
IndexError: list index out of range
